2024-10-08 18:44:47,181 - pyrogram.crypto.aes - WARNING - TgCrypto is missing! Pyrogram will work the same, but at a much slower speed. More info: https://docs.pyrogram.org/topics/speedups
2024-10-08 18:44:47,250 - apscheduler.scheduler - INFO - Scheduler started
2024-10-08 18:44:47,948 - __main__ - INFO - Received /start command from user: 7360250325
2024-10-08 18:44:47,949 - telegram.ext.dispatcher - ERROR - No error handlers are registered, logging exception.
Traceback (most recent call last):
  File "/usr/local/lib/python3.10/dist-packages/telegram/ext/dispatcher.py", line 555, in process_update
    handler.handle_update(update, self, check, context)
  File "/usr/local/lib/python3.10/dist-packages/telegram/ext/handler.py", line 198, in handle_update
    return self.callback(update, context)
  File "/home/user/Teraboxbot/main.py", line 49, in start
    update.message.reply_photo(photo=welcome_image_url, caption=start_text, parse_mode='HTML', reply_markup=reply_markup)
  File "/usr/local/lib/python3.10/dist-packages/telegram/message.py", line 1005, in reply_photo
    return self.bot.send_photo(
  File "/usr/local/lib/python3.10/dist-packages/telegram/bot.py", line 130, in decorator
    result = func(*args, **kwargs)
  File "/usr/local/lib/python3.10/dist-packages/telegram/bot.py", line 699, in send_photo
    return self._message(  # type: ignore[return-value]
  File "/usr/local/lib/python3.10/dist-packages/telegram/ext/extbot.py", line 199, in _message
    result = super()._message(
  File "/usr/local/lib/python3.10/dist-packages/telegram/bot.py", line 332, in _message
    result = self._post(endpoint, data, timeout=timeout, api_kwargs=api_kwargs)
  File "/usr/local/lib/python3.10/dist-packages/telegram/bot.py", line 295, in _post
    return self.request.post(
  File "/usr/local/lib/python3.10/dist-packages/telegram/utils/request.py", line 359, in post
    body=json.dumps(data).encode('utf-8'),
  File "/usr/lib/python3.10/json/__init__.py", line 231, in dumps
    return _default_encoder.encode(obj)
  File "/usr/lib/python3.10/json/encoder.py", line 199, in encode
    chunks = self.iterencode(o, _one_shot=True)
  File "/usr/lib/python3.10/json/encoder.py", line 257, in iterencode
    return _iterencode(o, 0)
  File "/usr/lib/python3.10/json/encoder.py", line 179, in default
    raise TypeError(f'Object of type {o.__class__.__name__} '
TypeError: Object of type InlineKeyboardMarkup is not JSON serializable
2024-10-08 18:44:47,955 - __main__ - INFO - Received video download request from user: 7360250325
2024-10-08 18:44:47,955 - __main__ - INFO - Checking if user 7360250325 has joined required channels
2024-10-08 18:44:49,146 - __main__ - INFO - Validating domain for URL: https://terasharelink.com/s/15G20LjZbN7pVEXFjDAbFBg
2024-10-08 18:44:49,760 - telegram.ext.dispatcher - ERROR - No error handlers are registered, logging exception.
Traceback (most recent call last):
  File "/usr/local/lib/python3.10/dist-packages/telegram/ext/dispatcher.py", line 555, in process_update
    handler.handle_update(update, self, check, context)
  File "/usr/local/lib/python3.10/dist-packages/telegram/ext/handler.py", line 198, in handle_update
    return self.callback(update, context)
  File "/home/user/Teraboxbot/main.py", line 268, in handle_download_video
    context.bot.loop.create_task(download_video(url, reply_msg, user_mention, user_id))
AttributeError: 'ExtBot' object has no attribute 'loop'
2024-10-08 18:44:49,761 - __main__ - INFO - Received video download request from user: 7360250325
2024-10-08 18:44:49,761 - __main__ - INFO - Checking if user 7360250325 has joined required channels
2024-10-08 18:44:50,136 - __main__ - INFO - Validating domain for URL: https://terasharelink.com/s/15G20LjZbN7pVEXFjDAbFBg
2024-10-08 18:44:50,443 - telegram.ext.dispatcher - ERROR - No error handlers are registered, logging exception.
Traceback (most recent call last):
  File "/usr/local/lib/python3.10/dist-packages/telegram/ext/dispatcher.py", line 555, in process_update
    handler.handle_update(update, self, check, context)
  File "/usr/local/lib/python3.10/dist-packages/telegram/ext/handler.py", line 198, in handle_update
    return self.callback(update, context)
  File "/home/user/Teraboxbot/main.py", line 268, in handle_download_video
    context.bot.loop.create_task(download_video(url, reply_msg, user_mention, user_id))
AttributeError: 'ExtBot' object has no attribute 'loop'
2024-10-08 18:44:50,445 - __main__ - INFO - Received video download request from user: 6670354006
2024-10-08 18:44:50,445 - __main__ - INFO - Checking if user 6670354006 has joined required channels
2024-10-08 18:44:51,328 - __main__ - INFO - Validating domain for URL: https://terasharelink.com/s/15G20LjZbN7pVEXFjDAbFBg
2024-10-08 18:44:51,631 - telegram.ext.dispatcher - ERROR - No error handlers are registered, logging exception.
Traceback (most recent call last):
  File "/usr/local/lib/python3.10/dist-packages/telegram/ext/dispatcher.py", line 555, in process_update
    handler.handle_update(update, self, check, context)
  File "/usr/local/lib/python3.10/dist-packages/telegram/ext/handler.py", line 198, in handle_update
    return self.callback(update, context)
  File "/home/user/Teraboxbot/main.py", line 268, in handle_download_video
    context.bot.loop.create_task(download_video(url, reply_msg, user_mention, user_id))
AttributeError: 'ExtBot' object has no attribute 'loop'
2024-10-08 18:44:51,632 - __main__ - INFO - Received video download request from user: 6670354006
2024-10-08 18:44:51,632 - __main__ - INFO - Checking if user 6670354006 has joined required channels
2024-10-08 18:44:51,996 - __main__ - INFO - Validating domain for URL: https://terasharelink.com/s/15G20LjZbN7pVEXFjDAbFBg
2024-10-08 18:44:52,350 - telegram.ext.dispatcher - ERROR - No error handlers are registered, logging exception.
Traceback (most recent call last):
  File "/usr/local/lib/python3.10/dist-packages/telegram/ext/dispatcher.py", line 555, in process_update
    handler.handle_update(update, self, check, context)
  File "/usr/local/lib/python3.10/dist-packages/telegram/ext/handler.py", line 198, in handle_update
    return self.callback(update, context)
  File "/home/user/Teraboxbot/main.py", line 268, in handle_download_video
    context.bot.loop.create_task(download_video(url, reply_msg, user_mention, user_id))
AttributeError: 'ExtBot' object has no attribute 'loop'
2024-10-08 18:44:52,351 - __main__ - INFO - Received /start command from user: 6670354006
2024-10-08 18:44:52,351 - telegram.ext.dispatcher - ERROR - No error handlers are registered, logging exception.
Traceback (most recent call last):
  File "/usr/local/lib/python3.10/dist-packages/telegram/ext/dispatcher.py", line 555, in process_update
    handler.handle_update(update, self, check, context)
  File "/usr/local/lib/python3.10/dist-packages/telegram/ext/handler.py", line 198, in handle_update
    return self.callback(update, context)
  File "/home/user/Teraboxbot/main.py", line 49, in start
    update.message.reply_photo(photo=welcome_image_url, caption=start_text, parse_mode='HTML', reply_markup=reply_markup)
  File "/usr/local/lib/python3.10/dist-packages/telegram/message.py", line 1005, in reply_photo
    return self.bot.send_photo(
  File "/usr/local/lib/python3.10/dist-packages/telegram/bot.py", line 130, in decorator
    result = func(*args, **kwargs)
  File "/usr/local/lib/python3.10/dist-packages/telegram/bot.py", line 699, in send_photo
    return self._message(  # type: ignore[return-value]
  File "/usr/local/lib/python3.10/dist-packages/telegram/ext/extbot.py", line 199, in _message
    result = super()._message(
  File "/usr/local/lib/python3.10/dist-packages/telegram/bot.py", line 332, in _message
    result = self._post(endpoint, data, timeout=timeout, api_kwargs=api_kwargs)
  File "/usr/local/lib/python3.10/dist-packages/telegram/bot.py", line 295, in _post
    return self.request.post(
  File "/usr/local/lib/python3.10/dist-packages/telegram/utils/request.py", line 359, in post
    body=json.dumps(data).encode('utf-8'),
  File "/usr/lib/python3.10/json/__init__.py", line 231, in dumps
    return _default_encoder.encode(obj)
  File "/usr/lib/python3.10/json/encoder.py", line 199, in encode
    chunks = self.iterencode(o, _one_shot=True)
  File "/usr/lib/python3.10/json/encoder.py", line 257, in iterencode
    return _iterencode(o, 0)
  File "/usr/lib/python3.10/json/encoder.py", line 179, in default
    raise TypeError(f'Object of type {o.__class__.__name__} '
TypeError: Object of type InlineKeyboardMarkup is not JSON serializable
2024-10-08 18:44:52,352 - __main__ - INFO - Received video download request from user: 6670354006
2024-10-08 18:44:52,352 - __main__ - INFO - Checking if user 6670354006 has joined required channels
2024-10-08 18:44:52,738 - __main__ - INFO - Validating domain for URL: https://terasharelink.com/s/15G20LjZbN7pVEXFjDAbFBg
2024-10-08 18:44:53,085 - telegram.ext.dispatcher - ERROR - No error handlers are registered, logging exception.
Traceback (most recent call last):
  File "/usr/local/lib/python3.10/dist-packages/telegram/ext/dispatcher.py", line 555, in process_update
    handler.handle_update(update, self, check, context)
  File "/usr/local/lib/python3.10/dist-packages/telegram/ext/handler.py", line 198, in handle_update
    return self.callback(update, context)
  File "/home/user/Teraboxbot/main.py", line 268, in handle_download_video
    context.bot.loop.create_task(download_video(url, reply_msg, user_mention, user_id))
AttributeError: 'ExtBot' object has no attribute 'loop'
2024-10-08 18:44:53,086 - __main__ - INFO - Received video download request from user: 6670354006
2024-10-08 18:44:53,086 - __main__ - INFO - Checking if user 6670354006 has joined required channels
2024-10-08 18:44:53,459 - __main__ - INFO - Validating domain for URL: https://terasharelink.com/s/15G20LjZbN7pVEXFjDAbFBg
2024-10-08 18:44:53,765 - telegram.ext.dispatcher - ERROR - No error handlers are registered, logging exception.
Traceback (most recent call last):
  File "/usr/local/lib/python3.10/dist-packages/telegram/ext/dispatcher.py", line 555, in process_update
    handler.handle_update(update, self, check, context)
  File "/usr/local/lib/python3.10/dist-packages/telegram/ext/handler.py", line 198, in handle_update
    return self.callback(update, context)
  File "/home/user/Teraboxbot/main.py", line 268, in handle_download_video
    context.bot.loop.create_task(download_video(url, reply_msg, user_mention, user_id))
AttributeError: 'ExtBot' object has no attribute 'loop'
2024-10-08 18:44:53,767 - __main__ - INFO - Received /start command from user: 6670354006
2024-10-08 18:44:53,767 - telegram.ext.dispatcher - ERROR - No error handlers are registered, logging exception.
Traceback (most recent call last):
  File "/usr/local/lib/python3.10/dist-packages/telegram/ext/dispatcher.py", line 555, in process_update
    handler.handle_update(update, self, check, context)
  File "/usr/local/lib/python3.10/dist-packages/telegram/ext/handler.py", line 198, in handle_update
    return self.callback(update, context)
  File "/home/user/Teraboxbot/main.py", line 49, in start
    update.message.reply_photo(photo=welcome_image_url, caption=start_text, parse_mode='HTML', reply_markup=reply_markup)
  File "/usr/local/lib/python3.10/dist-packages/telegram/message.py", line 1005, in reply_photo
    return self.bot.send_photo(
  File "/usr/local/lib/python3.10/dist-packages/telegram/bot.py", line 130, in decorator
    result = func(*args, **kwargs)
  File "/usr/local/lib/python3.10/dist-packages/telegram/bot.py", line 699, in send_photo
    return self._message(  # type: ignore[return-value]
  File "/usr/local/lib/python3.10/dist-packages/telegram/ext/extbot.py", line 199, in _message
    result = super()._message(
  File "/usr/local/lib/python3.10/dist-packages/telegram/bot.py", line 332, in _message
    result = self._post(endpoint, data, timeout=timeout, api_kwargs=api_kwargs)
  File "/usr/local/lib/python3.10/dist-packages/telegram/bot.py", line 295, in _post
    return self.request.post(
  File "/usr/local/lib/python3.10/dist-packages/telegram/utils/request.py", line 359, in post
    body=json.dumps(data).encode('utf-8'),
  File "/usr/lib/python3.10/json/__init__.py", line 231, in dumps
    return _default_encoder.encode(obj)
  File "/usr/lib/python3.10/json/encoder.py", line 199, in encode
    chunks = self.iterencode(o, _one_shot=True)
  File "/usr/lib/python3.10/json/encoder.py", line 257, in iterencode
    return _iterencode(o, 0)
  File "/usr/lib/python3.10/json/encoder.py", line 179, in default
    raise TypeError(f'Object of type {o.__class__.__name__} '
TypeError: Object of type InlineKeyboardMarkup is not JSON serializable
2024-10-08 18:44:53,767 - __main__ - INFO - Received /start command from user: 6670354006
2024-10-08 18:44:53,768 - telegram.ext.dispatcher - ERROR - No error handlers are registered, logging exception.
Traceback (most recent call last):
  File "/usr/local/lib/python3.10/dist-packages/telegram/ext/dispatcher.py", line 555, in process_update
    handler.handle_update(update, self, check, context)
  File "/usr/local/lib/python3.10/dist-packages/telegram/ext/handler.py", line 198, in handle_update
    return self.callback(update, context)
  File "/home/user/Teraboxbot/main.py", line 49, in start
    update.message.reply_photo(photo=welcome_image_url, caption=start_text, parse_mode='HTML', reply_markup=reply_markup)
  File "/usr/local/lib/python3.10/dist-packages/telegram/message.py", line 1005, in reply_photo
    return self.bot.send_photo(
  File "/usr/local/lib/python3.10/dist-packages/telegram/bot.py", line 130, in decorator
    result = func(*args, **kwargs)
  File "/usr/local/lib/python3.10/dist-packages/telegram/bot.py", line 699, in send_photo
    return self._message(  # type: ignore[return-value]
  File "/usr/local/lib/python3.10/dist-packages/telegram/ext/extbot.py", line 199, in _message
    result = super()._message(
  File "/usr/local/lib/python3.10/dist-packages/telegram/bot.py", line 332, in _message
    result = self._post(endpoint, data, timeout=timeout, api_kwargs=api_kwargs)
  File "/usr/local/lib/python3.10/dist-packages/telegram/bot.py", line 295, in _post
    return self.request.post(
  File "/usr/local/lib/python3.10/dist-packages/telegram/utils/request.py", line 359, in post
    body=json.dumps(data).encode('utf-8'),
  File "/usr/lib/python3.10/json/__init__.py", line 231, in dumps
    return _default_encoder.encode(obj)
  File "/usr/lib/python3.10/json/encoder.py", line 199, in encode
    chunks = self.iterencode(o, _one_shot=True)
  File "/usr/lib/python3.10/json/encoder.py", line 257, in iterencode
    return _iterencode(o, 0)
  File "/usr/lib/python3.10/json/encoder.py", line 179, in default
    raise TypeError(f'Object of type {o.__class__.__name__} '
TypeError: Object of type InlineKeyboardMarkup is not JSON serializable
2024-10-08 18:44:53,768 - __main__ - INFO - Received video download request from user: 6670354006
2024-10-08 18:44:53,768 - __main__ - INFO - Checking if user 6670354006 has joined required channels
2024-10-08 18:44:54,132 - __main__ - INFO - Validating domain for URL: https://github.com/xaekks/Teraboxbot
2024-10-08 18:44:54,132 - __main__ - WARNING - Invalid domain: github.com
2024-10-08 18:44:54,132 - __main__ - WARNING - Invalid domain for URL: https://github.com/xaekks/Teraboxbot
2024-10-08 18:44:54,452 - __main__ - INFO - Received video download request from user: 6670354006
2024-10-08 18:44:54,452 - __main__ - INFO - Checking if user 6670354006 has joined required channels
2024-10-08 18:44:54,836 - __main__ - INFO - Validating domain for URL: https://github.com/xaekks/Teraboxbot
2024-10-08 18:44:54,836 - __main__ - WARNING - Invalid domain: github.com
2024-10-08 18:44:54,836 - __main__ - WARNING - Invalid domain for URL: https://github.com/xaekks/Teraboxbot
2024-10-08 18:44:55,144 - __main__ - INFO - Received /start command from user: 7360250325
2024-10-08 18:44:55,144 - telegram.ext.dispatcher - ERROR - No error handlers are registered, logging exception.
Traceback (most recent call last):
  File "/usr/local/lib/python3.10/dist-packages/telegram/ext/dispatcher.py", line 555, in process_update
    handler.handle_update(update, self, check, context)
  File "/usr/local/lib/python3.10/dist-packages/telegram/ext/handler.py", line 198, in handle_update
    return self.callback(update, context)
  File "/home/user/Teraboxbot/main.py", line 49, in start
    update.message.reply_photo(photo=welcome_image_url, caption=start_text, parse_mode='HTML', reply_markup=reply_markup)
  File "/usr/local/lib/python3.10/dist-packages/telegram/message.py", line 1005, in reply_photo
    return self.bot.send_photo(
  File "/usr/local/lib/python3.10/dist-packages/telegram/bot.py", line 130, in decorator
    result = func(*args, **kwargs)
  File "/usr/local/lib/python3.10/dist-packages/telegram/bot.py", line 699, in send_photo
    return self._message(  # type: ignore[return-value]
  File "/usr/local/lib/python3.10/dist-packages/telegram/ext/extbot.py", line 199, in _message
    result = super()._message(
  File "/usr/local/lib/python3.10/dist-packages/telegram/bot.py", line 332, in _message
    result = self._post(endpoint, data, timeout=timeout, api_kwargs=api_kwargs)
  File "/usr/local/lib/python3.10/dist-packages/telegram/bot.py", line 295, in _post
    return self.request.post(
  File "/usr/local/lib/python3.10/dist-packages/telegram/utils/request.py", line 359, in post
    body=json.dumps(data).encode('utf-8'),
  File "/usr/lib/python3.10/json/__init__.py", line 231, in dumps
    return _default_encoder.encode(obj)
  File "/usr/lib/python3.10/json/encoder.py", line 199, in encode
    chunks = self.iterencode(o, _one_shot=True)
  File "/usr/lib/python3.10/json/encoder.py", line 257, in iterencode
    return _iterencode(o, 0)
  File "/usr/lib/python3.10/json/encoder.py", line 179, in default
    raise TypeError(f'Object of type {o.__class__.__name__} '
TypeError: Object of type InlineKeyboardMarkup is not JSON serializable
2024-10-08 18:44:55,145 - __main__ - INFO - Received /start command from user: 7360250325
2024-10-08 18:44:55,145 - telegram.ext.dispatcher - ERROR - No error handlers are registered, logging exception.
Traceback (most recent call last):
  File "/usr/local/lib/python3.10/dist-packages/telegram/ext/dispatcher.py", line 555, in process_update
    handler.handle_update(update, self, check, context)
  File "/usr/local/lib/python3.10/dist-packages/telegram/ext/handler.py", line 198, in handle_update
    return self.callback(update, context)
  File "/home/user/Teraboxbot/main.py", line 49, in start
    update.message.reply_photo(photo=welcome_image_url, caption=start_text, parse_mode='HTML', reply_markup=reply_markup)
  File "/usr/local/lib/python3.10/dist-packages/telegram/message.py", line 1005, in reply_photo
    return self.bot.send_photo(
  File "/usr/local/lib/python3.10/dist-packages/telegram/bot.py", line 130, in decorator
    result = func(*args, **kwargs)
  File "/usr/local/lib/python3.10/dist-packages/telegram/bot.py", line 699, in send_photo
    return self._message(  # type: ignore[return-value]
  File "/usr/local/lib/python3.10/dist-packages/telegram/ext/extbot.py", line 199, in _message
    result = super()._message(
  File "/usr/local/lib/python3.10/dist-packages/telegram/bot.py", line 332, in _message
    result = self._post(endpoint, data, timeout=timeout, api_kwargs=api_kwargs)
  File "/usr/local/lib/python3.10/dist-packages/telegram/bot.py", line 295, in _post
    return self.request.post(
  File "/usr/local/lib/python3.10/dist-packages/telegram/utils/request.py", line 359, in post
    body=json.dumps(data).encode('utf-8'),
  File "/usr/lib/python3.10/json/__init__.py", line 231, in dumps
    return _default_encoder.encode(obj)
  File "/usr/lib/python3.10/json/encoder.py", line 199, in encode
    chunks = self.iterencode(o, _one_shot=True)
  File "/usr/lib/python3.10/json/encoder.py", line 257, in iterencode
    return _iterencode(o, 0)
  File "/usr/lib/python3.10/json/encoder.py", line 179, in default
    raise TypeError(f'Object of type {o.__class__.__name__} '
TypeError: Object of type InlineKeyboardMarkup is not JSON serializable
2024-10-08 18:44:55,146 - __main__ - INFO - Received /start command from user: 7360250325
2024-10-08 18:44:55,146 - telegram.ext.dispatcher - ERROR - No error handlers are registered, logging exception.
Traceback (most recent call last):
  File "/usr/local/lib/python3.10/dist-packages/telegram/ext/dispatcher.py", line 555, in process_update
    handler.handle_update(update, self, check, context)
  File "/usr/local/lib/python3.10/dist-packages/telegram/ext/handler.py", line 198, in handle_update
    return self.callback(update, context)
  File "/home/user/Teraboxbot/main.py", line 49, in start
    update.message.reply_photo(photo=welcome_image_url, caption=start_text, parse_mode='HTML', reply_markup=reply_markup)
  File "/usr/local/lib/python3.10/dist-packages/telegram/message.py", line 1005, in reply_photo
    return self.bot.send_photo(
  File "/usr/local/lib/python3.10/dist-packages/telegram/bot.py", line 130, in decorator
    result = func(*args, **kwargs)
  File "/usr/local/lib/python3.10/dist-packages/telegram/bot.py", line 699, in send_photo
    return self._message(  # type: ignore[return-value]
  File "/usr/local/lib/python3.10/dist-packages/telegram/ext/extbot.py", line 199, in _message
    result = super()._message(
  File "/usr/local/lib/python3.10/dist-packages/telegram/bot.py", line 332, in _message
    result = self._post(endpoint, data, timeout=timeout, api_kwargs=api_kwargs)
  File "/usr/local/lib/python3.10/dist-packages/telegram/bot.py", line 295, in _post
    return self.request.post(
  File "/usr/local/lib/python3.10/dist-packages/telegram/utils/request.py", line 359, in post
    body=json.dumps(data).encode('utf-8'),
  File "/usr/lib/python3.10/json/__init__.py", line 231, in dumps
    return _default_encoder.encode(obj)
  File "/usr/lib/python3.10/json/encoder.py", line 199, in encode
    chunks = self.iterencode(o, _one_shot=True)
  File "/usr/lib/python3.10/json/encoder.py", line 257, in iterencode
    return _iterencode(o, 0)
  File "/usr/lib/python3.10/json/encoder.py", line 179, in default
    raise TypeError(f'Object of type {o.__class__.__name__} '
TypeError: Object of type InlineKeyboardMarkup is not JSON serializable
2024-10-08 18:44:55,146 - __main__ - INFO - Received /start command from user: 7360250325
2024-10-08 18:44:55,146 - telegram.ext.dispatcher - ERROR - No error handlers are registered, logging exception.
Traceback (most recent call last):
  File "/usr/local/lib/python3.10/dist-packages/telegram/ext/dispatcher.py", line 555, in process_update
    handler.handle_update(update, self, check, context)
  File "/usr/local/lib/python3.10/dist-packages/telegram/ext/handler.py", line 198, in handle_update
    return self.callback(update, context)
  File "/home/user/Teraboxbot/main.py", line 49, in start
    update.message.reply_photo(photo=welcome_image_url, caption=start_text, parse_mode='HTML', reply_markup=reply_markup)
  File "/usr/local/lib/python3.10/dist-packages/telegram/message.py", line 1005, in reply_photo
    return self.bot.send_photo(
  File "/usr/local/lib/python3.10/dist-packages/telegram/bot.py", line 130, in decorator
    result = func(*args, **kwargs)
  File "/usr/local/lib/python3.10/dist-packages/telegram/bot.py", line 699, in send_photo
    return self._message(  # type: ignore[return-value]
  File "/usr/local/lib/python3.10/dist-packages/telegram/ext/extbot.py", line 199, in _message
    result = super()._message(
  File "/usr/local/lib/python3.10/dist-packages/telegram/bot.py", line 332, in _message
    result = self._post(endpoint, data, timeout=timeout, api_kwargs=api_kwargs)
  File "/usr/local/lib/python3.10/dist-packages/telegram/bot.py", line 295, in _post
    return self.request.post(
  File "/usr/local/lib/python3.10/dist-packages/telegram/utils/request.py", line 359, in post
    body=json.dumps(data).encode('utf-8'),
  File "/usr/lib/python3.10/json/__init__.py", line 231, in dumps
    return _default_encoder.encode(obj)
  File "/usr/lib/python3.10/json/encoder.py", line 199, in encode
    chunks = self.iterencode(o, _one_shot=True)
  File "/usr/lib/python3.10/json/encoder.py", line 257, in iterencode
    return _iterencode(o, 0)
  File "/usr/lib/python3.10/json/encoder.py", line 179, in default
    raise TypeError(f'Object of type {o.__class__.__name__} '
TypeError: Object of type InlineKeyboardMarkup is not JSON serializable
2024-10-08 18:44:55,147 - __main__ - INFO - Received /start command from user: 6670354006
2024-10-08 18:44:55,147 - telegram.ext.dispatcher - ERROR - No error handlers are registered, logging exception.
Traceback (most recent call last):
  File "/usr/local/lib/python3.10/dist-packages/telegram/ext/dispatcher.py", line 555, in process_update
    handler.handle_update(update, self, check, context)
  File "/usr/local/lib/python3.10/dist-packages/telegram/ext/handler.py", line 198, in handle_update
    return self.callback(update, context)
  File "/home/user/Teraboxbot/main.py", line 49, in start
    update.message.reply_photo(photo=welcome_image_url, caption=start_text, parse_mode='HTML', reply_markup=reply_markup)
  File "/usr/local/lib/python3.10/dist-packages/telegram/message.py", line 1005, in reply_photo
    return self.bot.send_photo(
  File "/usr/local/lib/python3.10/dist-packages/telegram/bot.py", line 130, in decorator
    result = func(*args, **kwargs)
  File "/usr/local/lib/python3.10/dist-packages/telegram/bot.py", line 699, in send_photo
    return self._message(  # type: ignore[return-value]
  File "/usr/local/lib/python3.10/dist-packages/telegram/ext/extbot.py", line 199, in _message
    result = super()._message(
  File "/usr/local/lib/python3.10/dist-packages/telegram/bot.py", line 332, in _message
    result = self._post(endpoint, data, timeout=timeout, api_kwargs=api_kwargs)
  File "/usr/local/lib/python3.10/dist-packages/telegram/bot.py", line 295, in _post
    return self.request.post(
  File "/usr/local/lib/python3.10/dist-packages/telegram/utils/request.py", line 359, in post
    body=json.dumps(data).encode('utf-8'),
  File "/usr/lib/python3.10/json/__init__.py", line 231, in dumps
    return _default_encoder.encode(obj)
  File "/usr/lib/python3.10/json/encoder.py", line 199, in encode
    chunks = self.iterencode(o, _one_shot=True)
  File "/usr/lib/python3.10/json/encoder.py", line 257, in iterencode
    return _iterencode(o, 0)
  File "/usr/lib/python3.10/json/encoder.py", line 179, in default
    raise TypeError(f'Object of type {o.__class__.__name__} '
TypeError: Object of type InlineKeyboardMarkup is not JSON serializable
2024-10-08 18:44:55,147 - __main__ - INFO - Received /start command from user: 6670354006
2024-10-08 18:44:55,147 - telegram.ext.dispatcher - ERROR - No error handlers are registered, logging exception.
Traceback (most recent call last):
  File "/usr/local/lib/python3.10/dist-packages/telegram/ext/dispatcher.py", line 555, in process_update
    handler.handle_update(update, self, check, context)
  File "/usr/local/lib/python3.10/dist-packages/telegram/ext/handler.py", line 198, in handle_update
    return self.callback(update, context)
  File "/home/user/Teraboxbot/main.py", line 49, in start
    update.message.reply_photo(photo=welcome_image_url, caption=start_text, parse_mode='HTML', reply_markup=reply_markup)
  File "/usr/local/lib/python3.10/dist-packages/telegram/message.py", line 1005, in reply_photo
    return self.bot.send_photo(
  File "/usr/local/lib/python3.10/dist-packages/telegram/bot.py", line 130, in decorator
    result = func(*args, **kwargs)
  File "/usr/local/lib/python3.10/dist-packages/telegram/bot.py", line 699, in send_photo
    return self._message(  # type: ignore[return-value]
  File "/usr/local/lib/python3.10/dist-packages/telegram/ext/extbot.py", line 199, in _message
    result = super()._message(
  File "/usr/local/lib/python3.10/dist-packages/telegram/bot.py", line 332, in _message
    result = self._post(endpoint, data, timeout=timeout, api_kwargs=api_kwargs)
  File "/usr/local/lib/python3.10/dist-packages/telegram/bot.py", line 295, in _post
    return self.request.post(
  File "/usr/local/lib/python3.10/dist-packages/telegram/utils/request.py", line 359, in post
    body=json.dumps(data).encode('utf-8'),
  File "/usr/lib/python3.10/json/__init__.py", line 231, in dumps
    return _default_encoder.encode(obj)
  File "/usr/lib/python3.10/json/encoder.py", line 199, in encode
    chunks = self.iterencode(o, _one_shot=True)
  File "/usr/lib/python3.10/json/encoder.py", line 257, in iterencode
    return _iterencode(o, 0)
  File "/usr/lib/python3.10/json/encoder.py", line 179, in default
    raise TypeError(f'Object of type {o.__class__.__name__} '
TypeError: Object of type InlineKeyboardMarkup is not JSON serializable
2024-10-08 18:44:55,148 - __main__ - INFO - Received /start command from user: 6670354006
2024-10-08 18:44:55,148 - telegram.ext.dispatcher - ERROR - No error handlers are registered, logging exception.
Traceback (most recent call last):
  File "/usr/local/lib/python3.10/dist-packages/telegram/ext/dispatcher.py", line 555, in process_update
    handler.handle_update(update, self, check, context)
  File "/usr/local/lib/python3.10/dist-packages/telegram/ext/handler.py", line 198, in handle_update
    return self.callback(update, context)
  File "/home/user/Teraboxbot/main.py", line 49, in start
    update.message.reply_photo(photo=welcome_image_url, caption=start_text, parse_mode='HTML', reply_markup=reply_markup)
  File "/usr/local/lib/python3.10/dist-packages/telegram/message.py", line 1005, in reply_photo
    return self.bot.send_photo(
  File "/usr/local/lib/python3.10/dist-packages/telegram/bot.py", line 130, in decorator
    result = func(*args, **kwargs)
  File "/usr/local/lib/python3.10/dist-packages/telegram/bot.py", line 699, in send_photo
    return self._message(  # type: ignore[return-value]
  File "/usr/local/lib/python3.10/dist-packages/telegram/ext/extbot.py", line 199, in _message
    result = super()._message(
  File "/usr/local/lib/python3.10/dist-packages/telegram/bot.py", line 332, in _message
    result = self._post(endpoint, data, timeout=timeout, api_kwargs=api_kwargs)
  File "/usr/local/lib/python3.10/dist-packages/telegram/bot.py", line 295, in _post
    return self.request.post(
  File "/usr/local/lib/python3.10/dist-packages/telegram/utils/request.py", line 359, in post
    body=json.dumps(data).encode('utf-8'),
  File "/usr/lib/python3.10/json/__init__.py", line 231, in dumps
    return _default_encoder.encode(obj)
  File "/usr/lib/python3.10/json/encoder.py", line 199, in encode
    chunks = self.iterencode(o, _one_shot=True)
  File "/usr/lib/python3.10/json/encoder.py", line 257, in iterencode
    return _iterencode(o, 0)
  File "/usr/lib/python3.10/json/encoder.py", line 179, in default
    raise TypeError(f'Object of type {o.__class__.__name__} '
TypeError: Object of type InlineKeyboardMarkup is not JSON serializable
2024-10-08 18:44:55,148 - __main__ - INFO - Received /start command from user: 6670354006
2024-10-08 18:44:55,148 - telegram.ext.dispatcher - ERROR - No error handlers are registered, logging exception.
Traceback (most recent call last):
  File "/usr/local/lib/python3.10/dist-packages/telegram/ext/dispatcher.py", line 555, in process_update
    handler.handle_update(update, self, check, context)
  File "/usr/local/lib/python3.10/dist-packages/telegram/ext/handler.py", line 198, in handle_update
    return self.callback(update, context)
  File "/home/user/Teraboxbot/main.py", line 49, in start
    update.message.reply_photo(photo=welcome_image_url, caption=start_text, parse_mode='HTML', reply_markup=reply_markup)
  File "/usr/local/lib/python3.10/dist-packages/telegram/message.py", line 1005, in reply_photo
    return self.bot.send_photo(
  File "/usr/local/lib/python3.10/dist-packages/telegram/bot.py", line 130, in decorator
    result = func(*args, **kwargs)
  File "/usr/local/lib/python3.10/dist-packages/telegram/bot.py", line 699, in send_photo
    return self._message(  # type: ignore[return-value]
  File "/usr/local/lib/python3.10/dist-packages/telegram/ext/extbot.py", line 199, in _message
    result = super()._message(
  File "/usr/local/lib/python3.10/dist-packages/telegram/bot.py", line 332, in _message
    result = self._post(endpoint, data, timeout=timeout, api_kwargs=api_kwargs)
  File "/usr/local/lib/python3.10/dist-packages/telegram/bot.py", line 295, in _post
    return self.request.post(
  File "/usr/local/lib/python3.10/dist-packages/telegram/utils/request.py", line 359, in post
    body=json.dumps(data).encode('utf-8'),
  File "/usr/lib/python3.10/json/__init__.py", line 231, in dumps
    return _default_encoder.encode(obj)
  File "/usr/lib/python3.10/json/encoder.py", line 199, in encode
    chunks = self.iterencode(o, _one_shot=True)
  File "/usr/lib/python3.10/json/encoder.py", line 257, in iterencode
    return _iterencode(o, 0)
  File "/usr/lib/python3.10/json/encoder.py", line 179, in default
    raise TypeError(f'Object of type {o.__class__.__name__} '
TypeError: Object of type InlineKeyboardMarkup is not JSON serializable
2024-10-08 18:44:55,148 - __main__ - INFO - Received video download request from user: 6670354006
2024-10-08 18:44:55,148 - __main__ - INFO - Checking if user 6670354006 has joined required channels
2024-10-08 18:44:55,520 - __main__ - INFO - Validating domain for URL: https://terasharelink.com/s/15G20LjZbN7pVEXFjDAbFBg
2024-10-08 18:44:55,826 - telegram.ext.dispatcher - ERROR - No error handlers are registered, logging exception.
Traceback (most recent call last):
  File "/usr/local/lib/python3.10/dist-packages/telegram/ext/dispatcher.py", line 555, in process_update
    handler.handle_update(update, self, check, context)
  File "/usr/local/lib/python3.10/dist-packages/telegram/ext/handler.py", line 198, in handle_update
    return self.callback(update, context)
  File "/home/user/Teraboxbot/main.py", line 268, in handle_download_video
    context.bot.loop.create_task(download_video(url, reply_msg, user_mention, user_id))
AttributeError: 'ExtBot' object has no attribute 'loop'
2024-10-08 18:44:55,827 - __main__ - INFO - Received video download request from user: 6670354006
2024-10-08 18:44:55,827 - __main__ - INFO - Checking if user 6670354006 has joined required channels
2024-10-08 18:44:56,218 - __main__ - INFO - Validating domain for URL: https://terasharelink.com/s/15G20LjZbN7pVEXFjDAbFBg
2024-10-08 18:44:56,533 - telegram.ext.dispatcher - ERROR - No error handlers are registered, logging exception.
Traceback (most recent call last):
  File "/usr/local/lib/python3.10/dist-packages/telegram/ext/dispatcher.py", line 555, in process_update
    handler.handle_update(update, self, check, context)
  File "/usr/local/lib/python3.10/dist-packages/telegram/ext/handler.py", line 198, in handle_update
    return self.callback(update, context)
  File "/home/user/Teraboxbot/main.py", line 268, in handle_download_video
    context.bot.loop.create_task(download_video(url, reply_msg, user_mention, user_id))
AttributeError: 'ExtBot' object has no attribute 'loop'
2024-10-08 18:45:11,604 - __main__ - INFO - Received video download request from user: 6670354006
2024-10-08 18:45:11,604 - __main__ - INFO - Checking if user 6670354006 has joined required channels
